2024-07-21 20:09:58,466 INFO    StreamThr :2859637 [internal.py:wandb_internal():85] W&B internal server running at pid: 2859637, started at: 2024-07-21 20:09:58.464577
2024-07-21 20:09:58,468 DEBUG   HandlerThread:2859637 [handler.py:handle_request():158] handle_request: status
2024-07-21 20:09:58,473 INFO    WriterThread:2859637 [datastore.py:open_for_write():87] open: /home/eleni/workspace/flowers/SAPIENS_jax/purejaxrl/wandb/run-20240721_200958-1x74nzf6/run-1x74nzf6.wandb
2024-07-21 20:09:58,474 DEBUG   SenderThread:2859637 [sender.py:send():379] send: header
2024-07-21 20:09:58,555 DEBUG   SenderThread:2859637 [sender.py:send():379] send: run
2024-07-21 20:09:58,913 ERROR   SenderThread:2859637 [internal_api.py:execute():349] 403 response executing GraphQL.
2024-07-21 20:09:58,913 ERROR   SenderThread:2859637 [internal_api.py:execute():350] {"errors":[{"message":"permission denied","path":["upsertBucket"],"extensions":{"code":"PERMISSION_ERROR"}}],"data":{"upsertBucket":null}}
2024-07-21 20:09:58,914 ERROR   SenderThread:2859637 [sender.py:send_run():1009] It appears that you do not have permission to access the requested resource. Please reach out to the project owner to grant you access. If you have the correct permissions, verify that there are no issues with your networking setup.(Error 403: Forbidden)
Traceback (most recent call last):
  File "/home/eleni/anaconda3/envs/jax_sapiens/lib/python3.9/site-packages/wandb/sdk/lib/retry.py", line 131, in __call__
    result = self._call_fn(*args, **kwargs)
  File "/home/eleni/anaconda3/envs/jax_sapiens/lib/python3.9/site-packages/wandb/sdk/internal/internal_api.py", line 345, in execute
    return self.client.execute(*args, **kwargs)  # type: ignore
  File "/home/eleni/anaconda3/envs/jax_sapiens/lib/python3.9/site-packages/wandb/vendor/gql-0.2.0/wandb_gql/client.py", line 52, in execute
    result = self._get_result(document, *args, **kwargs)
  File "/home/eleni/anaconda3/envs/jax_sapiens/lib/python3.9/site-packages/wandb/vendor/gql-0.2.0/wandb_gql/client.py", line 60, in _get_result
    return self.transport.execute(document, *args, **kwargs)
  File "/home/eleni/anaconda3/envs/jax_sapiens/lib/python3.9/site-packages/wandb/sdk/lib/gql_request.py", line 59, in execute
    request.raise_for_status()
  File "/home/eleni/anaconda3/envs/jax_sapiens/lib/python3.9/site-packages/requests/models.py", line 1024, in raise_for_status
    raise HTTPError(http_error_msg, response=self)
requests.exceptions.HTTPError: 403 Client Error: Forbidden for url: https://api.wandb.ai/graphql

During handling of the above exception, another exception occurred:

Traceback (most recent call last):
  File "/home/eleni/anaconda3/envs/jax_sapiens/lib/python3.9/site-packages/wandb/sdk/internal/sender.py", line 1007, in send_run
    server_run = self._init_run(run, config_value_dict)
  File "/home/eleni/anaconda3/envs/jax_sapiens/lib/python3.9/site-packages/wandb/sdk/internal/sender.py", line 1079, in _init_run
    server_run, inserted, server_messages = self._api.upsert_run(
  File "/home/eleni/anaconda3/envs/jax_sapiens/lib/python3.9/site-packages/wandb/apis/normalize.py", line 73, in wrapper
    raise err
  File "/home/eleni/anaconda3/envs/jax_sapiens/lib/python3.9/site-packages/wandb/apis/normalize.py", line 41, in wrapper
    return func(*args, **kwargs)
  File "/home/eleni/anaconda3/envs/jax_sapiens/lib/python3.9/site-packages/wandb/sdk/internal/internal_api.py", line 2224, in upsert_run
    response = self.gql(
  File "/home/eleni/anaconda3/envs/jax_sapiens/lib/python3.9/site-packages/wandb/sdk/internal/internal_api.py", line 317, in gql
    ret = self._retry_gql(
  File "/home/eleni/anaconda3/envs/jax_sapiens/lib/python3.9/site-packages/wandb/sdk/lib/retry.py", line 147, in __call__
    retry_timedelta_triggered = check_retry_fn(e)
  File "/home/eleni/anaconda3/envs/jax_sapiens/lib/python3.9/site-packages/wandb/util.py", line 968, in check_retry_fn
    return fallback_retry_fn(e)
  File "/home/eleni/anaconda3/envs/jax_sapiens/lib/python3.9/site-packages/wandb/util.py", line 910, in no_retry_auth
    raise CommError(
wandb.errors.CommError: It appears that you do not have permission to access the requested resource. Please reach out to the project owner to grant you access. If you have the correct permissions, verify that there are no issues with your networking setup.(Error 403: Forbidden)
2024-07-21 20:10:03,921 DEBUG   HandlerThread:2859637 [handler.py:handle_request():158] handle_request: status_report
2024-07-21 20:10:08,922 DEBUG   HandlerThread:2859637 [handler.py:handle_request():158] handle_request: status_report
2024-07-21 20:10:13,923 DEBUG   HandlerThread:2859637 [handler.py:handle_request():158] handle_request: status_report
2024-07-21 20:10:18,924 DEBUG   HandlerThread:2859637 [handler.py:handle_request():158] handle_request: status_report
2024-07-21 20:10:23,925 DEBUG   HandlerThread:2859637 [handler.py:handle_request():158] handle_request: status_report
2024-07-21 20:10:28,926 DEBUG   HandlerThread:2859637 [handler.py:handle_request():158] handle_request: status_report
2024-07-21 20:10:33,928 DEBUG   HandlerThread:2859637 [handler.py:handle_request():158] handle_request: status_report
